Workbook
Name _Hlk222375674: 'IRC9'!$A$5

Sheet IRC1a
A1: 2026 SGOD PERFORMANCE MONITORING AND EVALUATION SYSTEM (SGOD PMES)
A2: Individual Report Card No. 1a
A3: Direction: Indicate the Monthly Customers Feedback Rating.
A4: TA Indicators | B4: Rating | N4: Ave.
B5: Jan | C5: Feb | D5: Mar | E5: Apr | F5: May | G5: Jun | H5: July | I5: Aug | J5: Sept | K5: Oct | L5: Nov | M5: Dec
A6: 1) Observes the schedule. | C6: 4 | D6: 4 | E6: 4 | F6: 3.96 | N6: =AVERAGE(B6:M6) -> 3.99
A7: 2) Establishes the objectives of the Technical Assistance. | C7: 3.88 | D7: 4 | E7: 3.94 | F7: 3.96 | N7: =AVERAGE(B7:M7) -> 3.945
A8: 3) Uses necessary tools/process/procedure for the conduct of TA. | C8: 3.88 | D8: 4 | E8: 4 | F8: 4 | N8: =AVERAGE(B8:M8) -> 3.97
A9: 4) Provide relevant, timely and appropriate Technical Assistance. | C9: 4 | D9: 4 | E9: 4 | F9: 3.96 | N9: =AVERAGE(B9:M9) -> 3.99
A10: 5) Understand the situation of schools in case may be, their needs, aspirations, plans, strength and weaknesses. | C10: 3.88 | D10: 4 | E10: 3.94 | F10: 4 | N10: =AVERAGE(B10:M10) -> 3.955
A11: 6) Recommends/suggests points for improvement. | C11: 4 | D11: 4 | E11: 4 | F11: 3.96 | N11: =AVERAGE(B11:M11) -> 3.99
A12: 7) Provides constructive feedback and establishes a cordial atmosphere in giving of feedback. | C12: 4 | D12: 4 | E12: 4 | F12: 3.96 | N12: =AVERAGE(B12:M12) -> 3.99
A13: 8) Skills and competencies of the TA provider. | C13: 4 | D13: 4 | E13: 4 | F13: 3.96 | N13: =AVERAGE(B13:M13) -> 3.99
A14: 9) Processes the results of the Technical Assistance. | C14: 3.88 | D14: 4 | E14: 4 | F14: 4 | N14: =AVERAGE(B14:M14) -> 3.97
A15: 10) General view of the provision of the Technical Assistance. | C15: 4 | D15: 4 | E15: 4 | F15: 4 | N15: =AVERAGE(B15:M15) -> 4
A16: Average | B16: =AVERAGE(B6:B15) -> #DIV/0! | C16: =AVERAGE(C6:C15) -> 3.952 | D16: =AVERAGE(D6:D15) -> 4 | E16: =AVERAGE(E6:E15) -> 3.988 | F16: =AVERAGE(F6:F15) -> 3.976 | G16: =AVERAGE(G6:G15) -> #DIV/0! | H16: =AVERAGE(H6:H15) -> #DIV/0! | I16: =AVERAGE(I6:I15) -> #DIV/0! | ... N16: =AVERAGE(N6:N15) -> 3.979
A17: Descriptive Value | B17: =IF(B16>=3.51, "Very Satisfactory", IF(B16>=2.51, "Satisfactory", IF(B16>=1.51, "Fair", "Poor"))) -> #DIV/0! | C17: =IF(C16>=3.51, "Very Satisfactory", IF(C16>=2.51, "Satisfactory", IF(C16>=1.51, "Fair", "Poor"))) -> Very Satisfactory | D17: =IF(D16>=3.51, "Very Satisfactory", IF(D16>=2.51, "Satisfactory", IF(D16>=1.51, "Fair", "Poor"))) -> Very Satisfactory | E17: =IF(E16>=3.51, "Very Satisfactory", IF(E16>=2.51, "Satisfactory", IF(E16>=1.51, "Fair", "Poor"))) -> Very Satisfactory | F17: =IF(F16>=3.51, "Very Satisfactory", IF(F16>=2.51, "Satisfactory", IF(F16>=1.51, "Fair", "Poor"))) -> Very Satisfactory | G17: =IF(G16>=3.51, "Very Satisfactory", IF(G16>=2.51, "Satisfactory", IF(G16>=1.51, "Fair", "Poor"))) -> #DIV/0! | H17: =IF(H16>=3.51, "Very Satisfactory", IF(H16>=2.51, "Satisfactory", IF(H16>=1.51, "Fair", "Poor"))) -> #DIV/0! | I17: =IF(I16>=3.51, "Very Satisfactory", IF(I16>=2.51, "Satisfactory", IF(I16>=1.51, "Fair", "Poor"))) -> #DIV/0! | ... N17: =IF(N16>=3.51, "Very Satisfactory", IF(N16>=2.51, "Satisfactory", IF(N16>=1.51, "Fair", "Poor"))) -> Very Satisfactory
A19: 1-B. Select the three "lowest" TA Indicators from the list. | D19: 1-C. Based on customer feedback, please list down one positive aspect and, if applicable, one opportunity for improvement (OFI).
A20: TA Indicators | B20: Ave. | D20: + | E20: Ms. Arian is easy to approach. She is always ready to help me improve and gives advice without hesitation. Thank you much po.
A21: 3) Uses necessary tools/process/procedure for the conduct of TA. | B21: =VLOOKUP(Table2[[#This Row],[TA Indicators]],A28:B39,2,FALSE) -> 3.97
A22: 2) Establishes the objectives of the Technical Assistance. | B22: =VLOOKUP(Table2[[#This Row],[TA Indicators]],A31:B40,2,FALSE) -> 3.945 | D22: - | E22: None
A23: 4) Provide relevant, timely and appropriate Technical Assistance. | B23: =VLOOKUP(Table2[[#This Row],[TA Indicators]],A32:B41,2,FALSE) -> 3.99
A25: Prepared by: | K25: Checked by:
A27: ARIAN MARIE B. SORIANO | K27: DR. JONATHAN P. DOMINGO
A28: Nurse II | K28: SGOD Chief
A31: TA Indicators | B31: Ave.
A32: 1) Observes the schedule. | B32: =N6 -> 3.99
A33: 2) Establishes the objectives of the Technical Assistance. | B33: =N7 -> 3.945
A34: 3) Uses necessary tools/process/procedure for the conduct of TA. | B34: =N8 -> 3.97
A35: 4) Provide relevant, timely and appropriate Technical Assistance. | B35: =N9 -> 3.99
A36: 5) Understand the situation of schools in case may be, their needs, aspirations, plans, strength and weaknesses. | B36: =N10 -> 3.955
A37: 6) Recommends/suggests points for improvement. | B37: =N11 -> 3.99
A38: 7) Provides constructive feedback and establishes a cordial atmosphere in giving of feedback. | B38: =N12 -> 3.99
A39: 8) Skills and competencies of the TA provider. | B39: =N13 -> 3.99
A40: 9) Processes the results of the Technical Assistance. | B40: =N14 -> 3.97
A41: 10) General view of the provision of the Technical Assistance. | B41: =N15 -> 4
A43: TA Indicators | B43: Ave.
A44: {=_xlfn._xlws.SORT(Table4[],2)} -> 2) Establishes the objectives of the Technical Assistance. | B44: 3.945
A45: 5) Understand the situation of schools in case may be, their needs, aspirations, plans, strength and weaknesses. | B45: 3.955
A46: 3) Uses necessary tools/process/procedure for the conduct of TA. | B46: 3.97
...

Sheet IRC1b
A1: 2026 SGOD PERFORMANCE MONITORING AND EVALUATION SYSTEM (SGOD PMES)
A2: Individual Report Card No. 1b
A3: Direction: Indicate the Number of Customers Served monthly.
A5: Month | B5: Number
A6: Jan
A7: Feb | B7: 8
A8: Mar | B8: 2
A9: Apr | B9: 17
A10: May | B10: 27
A11: Jun
A12: Jul
A13: Aug
A14: Sep
A15: Oct
A16: Nov
A17: Dec
A18: Total | B18: =SUM(B6:B17) -> 54
A22: Prepared by: | H22: Checked by:
A24: ARIAN MARIE B. SORIANO | H24: DR. JONATHAN P. DOMINGO
A25: Nurse II | H25: SGOD Chief

Sheet IRC2a
A1: 2026 SGOD PERFORMANCE MONITORING AND EVALUATION SYSTEM (SGOD PMES)
A2: Individual Report Card No. 2a
A3: Direction: Determine the Number of Schools Provided with TA.
A4: 1 | B4: Antipolo City Senior High School | C4: TRUE
A5: 2 | B5: Antipolo City SPED Center | C5: FALSE
A6: 3 | B6: Antipolo National Science and Technology HS | C6: TRUE
A7: 4 | B7: Antipolo NHS | C7: TRUE
A8: 5 | B8: Apia Integrated School | C8: TRUE
A9: 6 | B9: Bagong Nayon I ES | C9: FALSE
A10: 7 | B10: Bagong Nayon II ES | C10: FALSE
A11: 8 | B11: Bagong Nayon II NHS | C11: TRUE
A12: 9 | B12: Bagong Nayon IV ES | C12: FALSE
A13: 10 | B13: Binayoyo Integrated School | C13: TRUE
A14: 11 | B14: Cabading ES | C14: TRUE
A15: 12 | B15: Calawis ES | C15: FALSE
... A70: 67 | B70: Upper Kilingan ES | C70: TRUE
B71: Total | C71: =SUM(COUNTIFS(C4:C70,"TRUE")) -> 26
B72: Percentage | C72: =C71/67*100 -> 38.80597
B74: DEDP Priority Elementary Schools | C74: {=SUM(--(C9={TRUE}) + --(C10={TRUE}) + --(C12={TRUE}) + --(C19={TRUE}) + --(C24={TRUE}) + --(C28={TRUE}) + --(C29={TRUE}) + --(C31={TRUE}) + --(C35={TRUE}) + --(C36={TRUE}) + --(C37={TRUE}) + --(C41={TRUE}) + --(C43={TRUE}) + --(C50={TRUE}) + --(C51={TRUE}) + --(C53={TRUE}) + --(C55={TRUE}) + --(C56={TRUE}) + --(C68={TRUE}))} -> 3
B75: DEDP Priority Secondary Schools | C75: =COUNTIF(C7, TRUE) + COUNTIF(C11, TRUE) + COUNTIF(C23, TRUE) + COUNTIF(C38, TRUE) + COUNTIF(C40, TRUE) + COUNTIF(C57, TRUE) + COUNTIF(C58, TRUE) -> 4
A76: Total No. of DEDP Priority Schools Provided with TA | C76: =SUM(C74:C75) -> 7
A77: Percentage | C77: =C76/26*100 -> 26.923077 | E77: DEDP Priority Schools | F77: =C77 -> 26.923077
A78: Total No. of Non-DEDP Priority Schools Provided with TA | C78: {=SUM(--(C4:C6), --(C8), --(C13:C18), --(C20:C22), --(C25:C27), --(C30), --(C32:C34), --(C39), --(C42), --(C44:C49), --(C52), --(C54), --(C59:C67), --(C69:C70))} -> 19 | E78: Non-DEDP Priority Schools | F78: =C79 -> 46.341463
A79: Percentage | C79: =C78/41*100 -> 46.341463
A81: Prepared by:
A83: ARIAN MARIE B. SORIANO
A84: Nurse II
A87: Checked by:
A89: DR. JONATHAN P. DOMINGO
A90: SGOD Chief

Sheet IRC2b
A1: 2026 SGOD PERFORMANCE MONITORING AND EVALUATION SYSTEM (SGOD PMES)
A2: Individual Report Card No. 2b
A3: Direction: Determine the Frequency of TA Provided to DEDP Priority Schools.
A4: Elementary | C4: Q1 | D4: Q2 | E4: Q3 | F4: Q4 | G4: Total
A5: 1 | B5: Bagong Nayon I ES | C5: FALSE | D5: FALSE | E5: FALSE | F5: FALSE | G5: =COUNTIF(C5:F5, TRUE) -> 0
A6: 2 | B6: Bagong Nayon II ES | C6: FALSE | D6: FALSE | E6: FALSE | F6: FALSE | G6: =COUNTIF(C6:F6, TRUE) -> 0
A7: 3 | B7: Bagong Nayon IV ES | C7: FALSE | D7: FALSE | E7: FALSE | F7: FALSE | G7: =COUNTIF(C7:F7, TRUE) -> 0
A8: 4 | B8: Cupang ES | C8: FALSE | D8: FALSE | E8: FALSE | F8: FALSE | G8: =COUNTIF(C8:F8, TRUE) -> 0
A9: 5 | B9: Dela Paz ES | C9: FALSE | D9: FALSE | E9: FALSE | F9: FALSE | G9: =COUNTIF(C9:F9, TRUE) -> 0
A10: 6 | B10: Jesus S. Cabarrus ES | C10: FALSE | D10: FALSE | E10: FALSE | F10: FALSE | G10: =COUNTIF(C10:F10, TRUE) -> 0
A11: 7 | B11: Juan Sumulong ES | C11: FALSE | D11: FALSE | E11: FALSE | F11: FALSE | G11: =COUNTIF(C11:F11, TRUE) -> 0
A12: 8 | B12: Kaysakat ES | C12: FALSE | D12: FALSE | E12: FALSE | F12: FALSE | G12: =COUNTIF(C12:F12, TRUE) -> 0
A13: 9 | B13: Lores ES | C13: FALSE | D13: FALSE | E13: FALSE | F13: FALSE | G13: =COUNTIF(C13:F13, TRUE) -> 0
A14: 10 | B14: Mambugan I ES | C14: FALSE | D14: FALSE | E14: FALSE | F14: FALSE | G14: =COUNTIF(C14:F14, TRUE) -> 0
A15: 11 | B15: Mambugan II ES | C15: FALSE | D15: FALSE | E15: FALSE | F15: FALSE | G15: =COUNTIF(C15:F15, TRUE) -> 0
A16: 12 | B16: Mayamot ES | C16: FALSE | D16: FALSE | E16: FALSE | F16: FALSE | G16: =COUNTIF(C16:F16, TRUE) -> 0
... A23: 19 | B23: Tanza ES | C23: FALSE | D23: TRUE | E23: FALSE | F23: FALSE | G23: =COUNTIF(C23:F23, TRUE) -> 1
A24: Total | C24: =COUNTIF(C5:C23, TRUE) -> 1 | D24: =COUNTIF(D5:D23, TRUE) -> 2 | E24: =COUNTIF(E5:E23, TRUE) -> 0 | F24: =COUNTIF(F5:F23, TRUE) -> 0 | G24: =AVERAGE(C24:F24) -> 0.75
A25: Percentage | C25: =C24/19*100 -> 5.2631579 | D25: =D24/19*100 -> 10.526316 | E25: =E24/19*100 -> 0 | F25: =F24/19*100 -> 0 | G25: =AVERAGE(C25:F25) -> 3.9473684
A27: Secondary | C27: Q1 | D27: Q2 | E27: Q3 | F27: Q4 | G27: Total
A28: 1 | B28: Antipolo NHS | C28: FALSE | D28: TRUE | E28: FALSE | F28: FALSE | G28: =COUNTIF(C28:F28, TRUE) -> 1
A29: 2 | B29: Bagong Nayon II NHS | C29: FALSE | D29: TRUE | E29: FALSE | F29: FALSE | G29: =COUNTIF(C29:F29, TRUE) -> 1
A30: 3 | B30: Dalig NHS | C30: FALSE | D30: FALSE | E30: FALSE | F30: FALSE | G30: =COUNTIF(C30:F30, TRUE) -> 0
A31: 4 | B31: Mambugan NHS | C31: FALSE | D31: FALSE | E31: FALSE | F31: FALSE | G31: =COUNTIF(C31:F31, TRUE) -> 0
A32: 5 | B32: Maximo L. Gatlabayan MNHS | C32: FALSE | D32: FALSE | E32: FALSE | F32: FALSE | G32: =COUNTIF(C32:F32, TRUE) -> 0
A33: 6 | B33: San Isidro NHS | C33: FALSE | D33: TRUE | E33: FALSE | F33: FALSE | G33: =COUNTIF(C33:F33, TRUE) -> 1
A34: 7 | B34: San Jose NHS | C34: FALSE | D34: TRUE | E34: FALSE | F34: FALSE | G34: =COUNTIF(C34:F34, TRUE) -> 1
A35: Total | C35: =COUNTIF(C28:C34, TRUE) -> 0 | D35: =COUNTIF(D28:D34, TRUE) -> 4 | E35: =COUNTIF(E28:E34, TRUE) -> 0 | F35: =COUNTIF(F28:F34, TRUE) -> 0 | G35: =AVERAGE(C35:F35) -> 1
A36: Percentage | C36: =C35/7*100 -> 0 | D36: =D35/7*100 -> 57.142857 | E36: =E35/7*100 -> 0 | F36: =F35/7*100 -> 0 | G36: =AVERAGE(C36:F36) -> 14.285714
A39: Prepared by:
A41: ARIAN MARIE B. SORIANO
A42: Nurse II
A45: Checked by:
A47: DR. JONATHAN P. DOMINGO
A48: SGOD Chief

Sheet IRC3
A1: 2026 SGOD PERFORMANCE MONITORING AND EVALUATION SYSTEM (SGOD PMES)
A2: Individual Report Card No. 3
A3: Direction: Determine the Status of TA Provision to Schools based on the results of IRC2.
A4: Number of DEDP Priority Schools (Elem & Sec) Provided with TA | B4: OPCR/IPCR Score in terms of Efficiency | D4: Number of DEDP Schools that were not provided with TA | E4: Target No. of DEDP Priority Schools that will be provided with TA
A5: =IRC2a!C76 -> 7 | B5: =IF(A5>=25,5,IF(A5=24,4,IF(A5>=22,3,IF(A5=21,2,1)))) -> 1 | C5: 5) 96-100% (25-26) | D5: =26-A5 -> 19 | E5: 10
C6: 4) 91-95% (24)
C7: 3) 86-90% (22-23)
C8: 2) 81-85% (21)
C9: 1) 80% and below (20 & below)
A10: Number of Non-DEDP Priority Schools (Elem & Sec) Provided with TA | B10: OPCR/IPCR Score in terms of Efficiency | D10: Number of Non-DEDP Priority Schools that were not provided with TA | E10: Target No. of Non-DEDP Priority Schools that will be provided with TA
A11: =IRC2a!C78 -> 19 | B11: =IF(A11>=40,5,IF(A11>=37,4,IF(A11>=35,3,IF(A11=34,2,1)))) -> 1 | C11: 5) 96-100% (40-41) | D11: =41-A11 -> 22 | E11: 12
C12: 4) 91-95% (37-39)
C13: 3) 86-90% (35-36)
C14: 2) 81-85% (34)
C15: 1) 80% and below (33 & below)
A16: Total No. of Schools Provided with TA (Elem & Sec) | B16: OPCR/IPCR Score in terms of Efficiency | D16: Total No. of Schools that were not provided with TA | E16: Total target No. of Schools that will be provided with TA
A17: =SUM(A11,A5) -> 26 | B17: =IF(A17>=64,5,IF(A17>=60,4,IF(A17>=57,3,IF(A17>=54,2,1)))) -> 1 | C17: 5) 96-100% (64-67) | D17: =SUM(D5,D11) -> 41 | E17: =SUM(E11,E5) -> 22
C18: 4) 91-95% (60-63)
C19: 3) 86-90% (57-59)
C20: 2) 81-85% (54-56)
C21: 1) 80% and below (53 & below)
A23: Prepared by: | E23: Checked by:
A25: ARIAN MARIE B. SORIANO | E25: DR. JONATHAN P. DOMINGO
A26: Nurse II | E26: SGOD Chief

Sheet IRC4
A1: 2026 SGOD PERFORMANCE MONITORING AND EVALUATION SYSTEM (SGOD PMES)
A2: Individual Report Card No. 4
A3: Direction: Prepare a Technical Assistance (TA) Catch-up Plan based on the results of IRC3.
A4: Activity | B4: Objective/s | C4: School | D4: Schedule of TA | E4: TA Receiver | F4: MOV’s
A5: Specify the activity and project title | B5: List down at least three specific objectives | C5: Identify the schools that will be provided with TA per Month | E5: Identify the individuals who will be provided with TA | F5: List down the evidences
A6: SCHOOL MENTAL HEALTH PROGRAM | B6: 1. To capacitate new Guidance Designates in their roles and responsibilities. | C6: BN I ES, BN II ES, BN IV ES, Cupang ES, DPES, JSCES, JSES, Kaysakat ES, Lores ES, MBES I | D6: July | E6: School Head, School Guidance Coordinator | F6: TA Feedback Results, TA Agreement Form, OKD Monitoring Tool
B7: 2. To utilize the localize monitoring tool for SMHP. | C7: MBES II, Mayamot ES, Penafrancia ES, Rizza ES, SAVES, San Isidro ES | D7: August
B8: 3. To ensure inclusion of School Mental Health Program in the schools' AIP. | C8: Dalig NHS, Mambugan NHS, Maximo LGMNHS | D8: September
A10: Prepared by: | E10: Checked by:
A12: ARIAN MARIE B. SORIANO | E12: DR. JONATHAN P. DOMINGO
A13: Nurse II | E13: SGOD Chief
D59: January
D60: February
D61: March
D62: April
D63: May
D64: June
D65: July
D66: August
D67: September
D68: October
D69: November
D70: December

Sheet IRC5
A1: 2026 SGOD PERFORMANCE MONITORING AND EVALUATION SYSTEM (SGOD PMES)
A2: Individual Report Card No. 5
A3: Direction: Based on the Post Program Evaluation Results given by our SMME Section, please provide the required information in the table below. Write N/A if not applicable.
A4: No. | B4: Activity Title | C4: Date of Implementation | D4: Participants | E4: Overall Rating | F4: Descriptive Value | G4: Indicator with the Lowest Attained Rating | H4: Potential Cause for the Low Rating | I4: Corrective Measures to be Implemented
A5: 1
A6: 2
A7: 3
A8: 4
A9: 5
A12: Prepared by: | I12: Checked by:
A14: ARIAN MARIE B. SORIANO | I14: DR. JONATHAN P. DOMINGO
A15: Nurse II | I15: SGOD Chief
E17: DPCR | F17: OPCR | G17: GAA | H17: MATATAG | I17: BEDP
E18: Support to School Governance & Operations | F18: Curriculum Implementation | G18: Education Policy Development Program | H18: MAke the curriculum relevant to produce competent and job-ready, active, and responsible citizens. | I18: Access
E19: Planning & Research Management | F19: Support to School Governance & Operations | G19: Basic Education Inputs Program | H19: TAke steps to accelerate delivery of basic education facilities and services. | I19: Equity
E20: Community Level Linkages & Partnerships | F20: SDO Management | G20: Inclusive Education Program | H20: TAke good care of learners by promoting learner well-being, inclusive education, and a positive learning environment. | I20: Quality
E21: Human Resource Development | F21: Office Administration and Performance Management | G21: Support to Schools and Learners Program | H21: Give support to teachers to teach better. | I21: Resilience & Well-being
E22: Quality Assurance | G22: Education Human Resource Development Program | I22: Enabling Mechanism: Governance & Management
E23: Provision of Technical Assistance
E24: Office Administration & Performance Management
F66: Strongly Agree
F67: Agree
F68: Disagree
F69: Strongly Disagree
F70: N/A

Sheet IRC6
A1: 2026 SGOD PERFORMANCE MONITORING AND EVALUATION SYSTEM (SGOD PMES)
A2: Individual Report Card No. 6
A3: Direction: Supply the needed data for your Monitoring & Evaluation (M&E) Plan.
A4: Project Title: S.G.O.D | B4: Objectives | C4: Indicators | D4: Definition | E4: Data Collection | H4: Data Analysis | K4: Users of M&E results | L4: Reporting
E5: Source / Methods | F5: Person Responsible | G5: Frequency/ Schedule | H5: Data Used | I5: Person Responsible | J5: Frequency | L5: Communication Strategies | M5: Frequency / Schedule
A6: GOAL
A7: OUTCOME
A8: OUTPUT 1: Mid-Year Performance Review
A9: OUTPUT 2: Year-End Performance Evaluation
A11: Prepared by: | I11: Checked by:
A13: ARIAN MARIE B. SORIANO | I13: DR. JONATHAN P. DOMINGO
A14: Nurse II | I14: SGOD Chief

Sheet IRC7
A1: 2026 SGOD PERFORMANCE MONITORING AND EVALUATION SYSTEM (SGOD PMES)
A2: Individual Report Card No. 7
A3: Direction: Provide the needed data for the SGOD Dashboard.
G4: Referral Directory
A5: School ID | B5: School Name | C5: Curricular Offering | D5: District Learning Cluster (DLC) | E5: Status | F5: School Classification (2024) | G5: Functional | H5: Non - Functional
A6: 321507 | B6: Antipolo City National Science and Technology HS | C6: JHS with SHS | D6: II-D | E6: non-DEDP | F6: Small | G6: 1
A7: 342175 | B7: Antipolo City Senior HS | C7: Secondary | D7: I-A | E7: non-DEDP | F7: Large | G7: 1
A8: 500392 | B8: Antipolo City SPED Center | C8: Elementary | D8: I-B | E8: non-DEDP | F8: Small | G8: 1
A9: 301418 | B9: Antipolo NHS | C9: Secondary | D9: I-A | E9: DEDP | F9: Very Large | G9: 1
A10: 500391 | B10: Apia Integrated School | C10: Elementary | D10: II-F | E10: non-DEDP | F10: Small | G10: 1
A11: 500391 | B11: Apia Integrated School | C11: Secondary | D11: II-F | E11: non-DEDP | F11: Small | G11: 1
A12: 109319 | B12: Bagong Nayon I ES | C12: Elementary | D12: I-A | E12: DEDP | F12: Very Large | G12: 1
A13: 109320 | B13: Bagong Nayon II ES | C13: Elementary | D13: I-B | E13: DEDP | F13: Very Large | G13: 1
A14: 301419 | B14: Bagong Nayon II NHS | C14: JHS with SHS | D14: I-B | E14: DEDP | F14: Very Large | G14: 1
A15: 109321 | B15: Bagong Nayon IV ES | C15: Elementary | D15: I-B | E15: DEDP | F15: Very Large | G15: 1
A16: 501119 | B16: Binayoyo Integrated School | C16: Elementary | D16: II-F | E16: non-DEDP | F16: Small | G16: 1
A17: 501119 | B17: Binayoyo Integrated School | C17: Secondary | D17: II-F | E17: non-DEDP | F17: Small | G17: 1
... A27: 321506 | B27: Dalig NHS | C27: JHS with SHS | D27: II-B | E27: DEDP | F27: Large | G27: 1
B28: Dela Paz ES | C28: Elementary | D28: I-A | E28: DEDP | F28: Large | G28: 1
A29: 321505 | B29: Dela Paz NHS | C29: JHS with SHS | D29: I-A | E29: non-DEDP | F29: Large | G29: 1
A30: 109326 | B30: Inuman ES | C30: Elementary | D30: II-D | E30: non-DEDP | F30: Large | G30: 1
A31: 109350 | B31: Isaias S. Tapales ES | C31: Elementary | D31: II-B | E31: non-DEDP | F31: Very Large | G31: 1
A32: 109351 | B32: Jesus S. Cabarrus ES | C32: Elementary | D32: II-B | E32: DEDP | F32: Large | G32: 1
A33: 109327 | B33: Juan Sumulong ES | C33: Elementary | D33: II-A | E33: DEDP | F33: Very Large | G33: 1
A34: 109328 | B34: Kaila ES | C34: Elementary | D34: II-A | E34: non-DEDP | F34: Medium | G34: 1
A35: 109352 | B35: Kaysakat ES | C35: Elementary | D35: II-G | E35: DEDP | F35: Small | G35: 1
A36: 301421 | B36: Kaysakat NHS | C36: JHS with SHS | D36: II-G | E36: non-DEDP | F36: Small | G36: 1
A37: 230003 | B37: Knights of Columbus ES | C37: Elementary | D37: II-A | E37: non-DEDP | F37: Medium | G37: 1
A38: 109322 | B38: Libis ES | C38: Elementary | D38: II-G | E38: non-DEDP | F38: Small | G38: 1
A39: 109329 | B39: Lores ES | C39: Elementary | D39: II-A | E39: DEDP | F39: Large | G39: 1
A40: 109330 | B40: Mambugan I ES | C40: Elementary | D40: I-C | E40: DEDP | F40: Large | G40: 1
... A74: 109363 | B74: Upper Kilingan ES | C74: Elementary | D74: II-E | E74: non-DEDP | F74: Small | G74: 1
G76: 69 | H76: 0
B78: Prepared by: | F78: Checked by:
B80: ARIAN MARIE B. SORIANO | F80: DR. JONATHAN P. DOMINGO
B81: Nurse II | F81: SGOD Chief

Sheet IRC8a
A1: INDIVIDUAL PERFORMANCE COMMITMENT AND REVIEW FORM (IPCRF)
A3: Name of Employee : ARIAN MARIE B. SORIANO, RN | H3: Name of Rater : DR. JONATHAN P. DOMINGO
A4: Position : NURSE II | H4: Position : SGOD CHIEF
A5: Bureau/Center/Service/Division : CITY SCHOOLS DIVISION OFFICE OF ANTIPOLO – SGOD | H5: Date of Review :
A6: Rating Period : JANUARY 2026 - DECEMBER 2026
A8: TO BE FILLED DURING PLANNING | I8: TO BE FILLED DURING EVALUATION
A9: MFOs | B9: KRAs | C9: OBJECTIVES | D9: TIME LINE | E9: Weight per KRA | F9: PERFORMANCE INDICATORS | I9: MOVs | J9: ACTUAL RESULTS | K9: RATING | O9: Score
F10: Quality | G10: Efficiency | H10: Timeliness | K10: Q | L10: E | M10: T | N10: Ave
A11: Basic Education Services | B11: PARTNERS AND DONORS | C11: A. Prepared draft agreements to establish and maintain partnerships with stakeholders 3 weeks after MOA/agreements was finalized. (2%) | D11: January to December 2026 | E11: 0.1 | F11: 5 - Facilitated signing of MOA/Agreements/DOD with stakeholders/partners and successfully conducted the activity. | H11: 5 - 1 week after the MOA/Agreements was finalized. | J11: Communicated with potential partners and donors requesting for meeting and discussion of project details. | K11: 2 | M11: 1 | N11: =AVERAGE(K11:M15) -> 1.5 | O11: =N11*0.02 -> 0.03
F12: 4 - Submitted draft agreements to Medical Officer and SMN section for review and held a meeting with the stakeholder. | H12: 4 - 2 weeks after the MOA/Agreements was finalized.
F13: 3 - Prepared draft agreements to establish and maintain partnerships with stakeholders. | H13: 3 - 3 weeks after the MOA/Agreements was finalized.
F14: 2 - Communicated with potential partners and donors requesting for meeting and discussion of project details. | H14: 2 - 4 weeks after the MOA/Agreements was finalized.
F15: 1 - Identified potential partners and donors in promoting health, nutrition well-being of workers and learners. | H15: 1 - 5 weeks after the MOA/Agreements was finalized.
C16: B. Conducted activities with the stakeholders/partners to sustain partnership until the fourth week of October of the current year. (6%) | D16: September to October 2026 | F16: 5 - Submitted reports to Medical Officer and uploaded in the Data Management System. | H16: 5 - Until the second week of October of the current year. | J16: Discussed details of the proposed activities with TWG. | K16: 2 | M16: 1 | N16: =AVERAGE(K16:M20) -> 1.5 | O16: =N16*0.06 -> 0.09
F17: 4 - Presented program activity results to MO/Chief SGOD and uploaded in the Data Management System | H17: 4 - Until the third week of October of the current year.
F18: 3 - Conducted activities with the stakeholders/partners to sustain partnership | H18: 3 - Until the fourth week of October of the current year.
F19: 2 - Discussed details of the proposed activities with TWG. | H19: 2 - Until the first week of November of the current year.
F20: 1 - Planned and scheduled the conduct of activity with stakeholders/partners. | H20: 1 - Until the second week of November of the current year.
A21: Basic Education Services | B21: PARTNERS AND DONORS | C21: C. Prepared draft memorandum to recognize stakeholders/partners in order to highlight and promote their advocacy (2%) | D21: September to October 2026 | F21: 5 - Recognize stakeholders/partners to highlight and promote their advocacy. | H21: 5 - during the conduct of the activity. | J21: Discussed details of the proposed activities with TWG. | K21: 2 | M21: 1 | N21: =AVERAGE(K21:M25) -> 1.5 | O21: =N21*0.02 -> 0.03
F22: 4 - Submitted the prepared draft memorandum on the recognition of stakeholders/partners to highlight and promote their advocacy | H22: 4 - 1 week after the activity has been conducted.
F23: 3 - Prepared draft memorandum on the recognition of stakeholders/partners to highlight and promote their advocacy | H23: 3 - 2 weeks after the activity has been conducted.
F24: 2 - Discussed details of the proposed activities with TWG. | H24: 2 - Until the second week of December of the current year.
F25: 1 - Planned and scheduled the conduct of activity with stakeholders/partners. | H25: 1 - Until the third week of December of the current year.
B26: PROGRAMS AND SERVICES | C26: A. Made available 4 health and nutrition programs and services aligned with Project GEMS until first week of December of the current year. (30%) | D26: January to December 2025 | E26: 0.7 | F26: 5 - Submitted consolidated report to Medical Officer and uploaded in the Data Management System. | G26: 5 -Made available 6 health and nutrition programs and services aligned with Project GEMS | H26: 5 - Until the third week of November of the current year. | J26: Communicated the schedule of nutrition programs and services. | K26: 2 | L26: 1 | M26: 1 | N26: =AVERAGE(K26:M30) -> 1.3333333 | O26: =N26*0.3 -> 0.4
F27: 4 - Consolidated the result per program. | G27: 4 - 5 health and nutrition programs and services | H27: 4 - Until the fourth week of November of the current year.
F28: 3 - Made available health and nutrition programs and services aligned with Project GEMS. | G28: 3 - 4 health and nutrition programs and services | H28: 3 - Until the first week of December of the current year.
F29: 2 - Communicated the schedule of nutrition programs and services. | G29: 2 - 3 health and nutrition programs and services | H29: 2 - Until the second week of December of the current year.
F30: 1 - Planned the schedule for the nutrition programs and services. | G30: 1 - 2 health and nutrition programs and service. | H30: 1 - Until the third week of December of the current year.
C31: B. Assessed, monitored and evaluated health status of 86%-90% (1291-1364) learners until first week of December of the current year. (10%) | F31: 5 - Submitted consolidated individual health status to the Medical Officer. | G31: 5 - Assessed, monitored and evaluated health status of 96%-100% (1440-1500) learners. | H31: 5 - Until the third week of November of the current year. | J31: Secured approval for schedule of assessment and monitoring of individual health status. | K31: 2 | L31: 1 | M31: 1 | N31: =AVERAGE(K31:M35) -> 1.3333333 | O31: =N31*0.1 -> 0.13333333
F32: 4 - Consolidated result of assessment and monitoring of individual health status. | G32: 4 - 91%-95% (1365-1439) learners | H32: 4 - Until the fourth week of November of the current year.
F33: 3 - Assessed and monitored individual health status. | G33: 3 -86%-90% (1291-1364) learners | H33: 3 - Until the first week of December of the current year.
F34: 2 - Secured approval for schedule of assessment and monitoring of individual health status. | G34: 2 - 81%-85% (1215-1290) learners | H34: 2 - Until the second week of December of the current year.
F35: 1 - Created schedule of assessment and monitoring of individual health status. | G35: 1 - Below 80% (1214 & below) learners | H35: 1 - Until the third week of December of the current year.
A36: Basic Education Services | B36: PROGRAMS AND SERVICES | C36: C. Assessed, monitored and evaluated health status of 60%-79% (150-199) teaching and non-teaching personnel until first week of December of the current year. (10%) | D36: January to December 2025 | F36: 5 - Submitted consolidated individual health status to the Medical Officer and uploaded in the Data Management System. | G36: 5 - Assessed, monitored and evaluated health status of 96-100% (240-250) teaching and non-teaching personnel. | H36: 5 - Until the third week of November of the current year. | J36: Secured approval for schedule of assessment and monitoring of individual health status. | K36: 2 | L36: 1 | M36: 1 | N36: =AVERAGE(K36:M40) -> 1.3333333 | O36: =N36*0.1 -> 0.13333333
F37: 4 - Consolidated result of assessment and monitoring of individual health status. | G37: 4 - 91%-95% (228-239) teaching and non-teaching personnel. | H37: 4 - Until the fourth week of November of the current year.
F38: 3 - Assessed, monitored and evaluated health status | G38: 3 -86%-90% (215-227) teaching and non-teaching personnel. | H38: 3 - Until the first week of December of the current year.
F39: 2 - Secured approval for schedule of assessment and monitoring of individual health status. | G39: 2 - 81-85% (202-214) teaching and non-teaching personnel. | H39: 2 - Until the second week of December of the current year.
F40: 1 - Created schedule of assessment and monitoring of individual health status. | G40: 1 - Below 80% (201 and below) teaching and non-teaching personnel. | H40: 1 - Until the third week of December of the current year.
C41: D. Provided nursing services to 8 activities/ programs/ trainings/ workshops/ seminars of the division, region or national with documentation until the first week of December of the current year. (20%) | F41: 5 - Submitted consolidated report to Medical Officer and uploaded in the Data Management System. | G41: 5 - Provided nursing assistance to 10 activities/ programs/ trainings/ workshops/ seminars. | H41: 5 - Until the third week of November of the current year. | J41: Communicated the schedule of provision of TA with SHN section. | K41: 2 | L41: 1 | M41: 1 | N41: =AVERAGE(K41:M45) -> 1.3333333 | O41: =N41*0.2 -> 0.26666667
F42: 4 - Consolidated the result per activities/ programs/ trainings/ workshops/ seminars. | G42: 4 - Provided nursing assistance to 9 activities/ programs/ trainings/ workshops/ seminars. | H42: 4 - Until the fourth week of November of the current year.
...

Sheet IRC8b
A2: Name of Employee: ARIAN MARIE B. SORIANO | F2: Division: Antipolo City
A3: Position: NURSE II | F3: Calendar Year: 2026
A5: CORE BEHAVIORAL COMPETENCIES
A7: Self Management | D7: =AVERAGE(D8:D12) -> 4.6 | F7: Teamwork | I7: =AVERAGE(I8:I12) -> 4.2
A8: 1 | B8: Sets personal goals and direction, needs and development. | D8: 5 | F8: 1 | G8: Willingly does his/her share of responsibility. | I8: 5
A9: 2 | B9: Undertakes personal actions and behaviors that are clear and purposive and takes into account personal goals and values congruent to that of the organization. | D9: 5 | F9: 2 | G9: Promotes collaboration and removes barriers to teamwork and goal accomplishment across the organization. | I9: 4
A10: 3 | B10: Displays emotional maturity and enthusiasm for and is challenged by higher goals. | D10: 5 | F10: 3 | G10: Applies negotiation principles in arriving at win-win agreements. | I10: 4
A11: 4 | B11: Prioritize work tasks and schedules (through gantt charts, checklists, etc.) to achieve goals. | D11: 4 | F11: 4 | G11: Drives consensus and team ownership of decisions. | I11: 4
A12: 5 | B12: Sets high quality, challenging, realistic goals for self and others. | D12: 4 | F12: 5 | G12: Works constructively and collaboratively with others and across organizations to accomplish organizational goals and objectives. | I12: 4
A14: Professionalism and Ethics | D14: =AVERAGE(D15:D19) -> 4.4 | F14: Service Orientation | I14: =AVERAGE(I15:I19) -> 4.6
A15: 1 | B15: Demonstrates the values and behavior enshrined in the Norms of Conduct and Ethical Standards for public officials and employees (RA 6713). | D15: 4 | F15: 1 | G15: Can explain and articulate organizational directions, issues and problems. | I15: 4
A16: 2 | B16: Practices ethical and professional behavior and conduct taking into account the impact of his/her actions and decisions. | D16: 5 | F16: 2 | G16: Takes personal responsibility for dealing with and/or correcting customer service issues and concerns. | I16: 5
A17: 3 | B17: Maintains a professional image: being trustworthy, regularity of attendance and punctuality, good grooming and communication. | D17: 5 | F17: 3 | G17: Initiates activities that promotes advocacy for men and women empowerment. | I17: 5
A18: 4 | B18: Makes personal sacrifices to meet the organization’s needs. | D18: 4 | F18: 4 | G18: Participates in updating of office vision, mission, mandates and strategies based on DepEd strategies and directions. | I18: 4
A19: 5 | B19: Acts with a sense of urgency and responsibility to meet the organization’s needs, improve systems and help others improve their effectiveness. | D19: 4 | F19: 5 | G19: Develops and adopts service improvement programs through simplified procedures that will further enhance service delivery. | I19: 5
A21: Result Focus | D21: =AVERAGE(D22:D26) -> 4.4 | F21: Innovation | I21: =AVERAGE(I22:I26) -> 4
A22: 1 | B22: Achieves results with optimal use of time and resources most of the time. | D22: 4 | F22: 1 | G22: Examines the root cause of problems and suggests effective solutions. Fosters new ideas, processes, and suggests better ways to do things (cost and/or operational efficiency). | I22: 4
A23: 2 | B23: Avoids rework, mistakes and wastage through effective work methods by placing organizational needs before personal needs. | D23: 4 | F23: 2 | G23: Demonstrates an ability to think “beyond the box”. Continuously focuses on improving personal productivity to create higher value and results. | I23: 4
A24: 3 | B24: Delivers error-free outputs most of the time by conforming to standard operating procedures correctly and consistently. Able to produce very satisfactory quality of work In terms of usefulness/acceptability and completeness with no supervision required. | D24: 4 | F24: 3 | G24: Promotes a creative climate and inspires co – workers to develop original ideas or solutions. | I24: 4
A25: 4 | B25: Expresses a desire to do better and may express frustration at waste or inefficiency. May focus on new or more precise ways of meeting goals set. | D25: 5 | F25: 4 | G25: Translates creative thinking into tangible changes and solutions that improve the work unit and organization. | I25: 4
A26: 5 | B26: Makes specific changes in the system or in own work methods to improve performance. Examples may include doing something better, faster, at a lower cost, more efficiently; or improving quality, customer satisfaction, morale, without setting any specific goal. | D26: 5 | F26: 5 | G26: Uses ingenious methods to accomplish responsibilities. Demonstrates resourcefulness and the ability to succeed with minimal resources. | I26: 4
B28: 5 - Role model; 4 - Consistently demonstrate; 3 - Most of the time demonstrate; 2 - Sometimes demonstrate; 1 - Rarely demonstrate
A30: CORE SKILLS
A32: Achievement | D32: =AVERAGE(D33:D37) -> 4
A33: 1 | B33: Enjoys working hard. | D33: 4
A34: 2 | B34: Is action – oriented and full of energy for the things he/she sees as challenging. | D34: 4
A35: 3 | B35: Not fearful of acting with a minimum of planning. | D35: 4
A36: 4 | B36: Seizes more opportunities than others. | D36: 4
A37: 5 | B37: Strategic thinker. | D37: 4
A39: Managing Diversity | D39: =AVERAGE(D40:D44) -> 4.8
A40: 1 | B40: Respects all kinds and classes of people. | D40: 5
A41: 2 | B41: Deals effectively with all races, nationalities, cultures, disabilities, ages and both sexes. | D41: 5
A42: 3 | B42: Support equal and fair treatment and opportunity for all. | D42: 5
A43: 4 | B43: Applies equal standards and criteria to all classes. | D43: 5
A44: 5 | B44: Manifests cultural and gender sensitivity when dealing with people. | D44: 4
A46: Accountability | D46: =AVERAGE(D47:D51) -> 4.2
A47: 1 | B47: Can be counted on to exceed goals successfully. | D47: 5
A48: 2 | B48: Steadfastly pushes self and others towards results. | D48: 4
A49: 3 | B49: Gets things done on time and optimum use of resources. | D49: 4
A50: 4 | B50: Builds team spirit. | D50: 4
...

Sheet IRC8c
A1: PART II: SUMMARY OF RATINGS FOR DISCUSSION
B3: Final Performance Results Rating | C3: =IRC8a!O61 -> 1.35
B4: Accomplishments of KRAs and Objectives | C4: P
A6: Employee-Superior Agreement
A8: The signature below confirm that the employee and his/her superior have agreed to the contents of the performance as captured in this form
A10: Name of Employee | B10: ARIAN MARIE B. SORIANO | C10: Name of Superior | D10: DR. JONATHAN P. DOMINGO
A11: Signature | C11: Signature
A12: Date | C12: Date
A14: PART IV: DEVELOPMENT PLANS
A16: STRENGTHS | B16: DEVELOPMENT NEEDS | C16: ACTION PLAN (Recommended Developmental Intervention) | D16: Timeline | E16: Resources Needed
A17: Sets personal goals and direction, needs and development. | B17: Demonstrates an ability to think “beyond the box”. Continuously focuses on improving personal productivity to create higher value and results. | C17: Self-Management learning, Coaching and Counseling | D17: January to December 2026 | E17: Human Resources
A18: Undertakes personal actions and behaviors that are clear and purposive and takes into account personal goals and values congruent to that of the organization. | B18: Promotes a creative climate and inspires co – workers to develop original ideas or solutions. | C18: Self-Management learning, Coaching and Counseling | D18: January to December 2026 | E18: Human Resources
A19: Practices ethical and professional behavior and conduct taking into account the impact of his/her actions and decisions. | B19: Translates creative thinking into tangible changes and solutions that improve the work unit and organization. | C19: Self-Management learning, Coaching and Counseling | D19: January to December 2026 | E19: Human Resources
A20: Maintains a professional image: being trustworthy, regularity of attendance and punctuality, good grooming and communication. | B20: Uses ingenious methods to accomplish responsibilities. Demonstrates resourcefulness and the ability to succeed with minimal resources. | C20: Self-Management learning, Coaching and Counseling | D20: January to December 2026 | E20: Human Resources
A23: ARIAN MARIE B. SORIANO | C23: DR. JONATHAN P. DOMINGO
A24: NURSE II | C24: CHIEF SGOD

Sheet IRC8d
A1: PART III: SUMMARY OF RATINGS FOR DISCUSSION
A2: MFOs | B2: KRAs | C2: OBJECTIVES | D2: TIME LINE | E2: Weight per KRA | F2: ACTUAL RESULTS | G2: RATING | K2: Score
G3: Q | H3: E | I3: T | J3: Ave
A4: Basic Education Sector | B4: PARTNERS AND DONORS | C4: A. Prepared draft agreements to establish and maintain partnerships with stakeholders 3 weeks after MOA/agreements was finalized. (2%) | D4: year round | E4: 0.1 | F4: Communicated with potential partners and donors requesting for meeting and discussion of project details. | G4: =IRC8a!K11 -> 2 | I4: =IRC8a!M11 -> 1 | J4: =AVERAGE(G4:I4) -> 1.5 | K4: =J4*0.02 -> 0.03
C5: B. Conducted activities with the stakeholders/partners to sustain partnership until the fourth week of October of the current year. (6%) | D5: year round | F5: Discussed details of the proposed activities with TWG. | G5: =IRC8a!K16 -> 2 | I5: =IRC8a!M16 -> 1 | J5: =AVERAGE(G5:I5) -> 1.5 | K5: =J5*0.06 -> 0.09
C6: C. Prepared draft memorandum to recognize stakeholders/partners in order to highlight and promote their advocacy (2%) | D6: year round | F6: Discussed details of the proposed activities with TWG. | G6: =IRC8a!K21 -> 2 | I6: =IRC8a!M21 -> 1 | J6: =AVERAGE(G6:I6) -> 1.5 | K6: =J6*0.02 -> 0.03
B7: PROGRAMS AND SERVICES | C7: A. Made available 4 health and nutrition programs and services aligned with Project GEMS until first week of December of the current year. (30%) | D7: year round | E7: 0.7 | F7: Communicated the schedule of nutrition programs and services. | G7: =IRC8a!K26 -> 2 | H7: =IRC8a!L26 -> 1 | I7: =IRC8a!M26 -> 1 | J7: =AVERAGE(G7:I7) -> 1.3333333 | K7: =J7*0.3 -> 0.4
C8: B. Assessed, monitored and evaluated health status of 86%-90% (1291-1364) learners until first week of December of the current year. (10%) | D8: year round | F8: Secured approval for schedule of assessment and monitoring of individual health status. | G8: =IRC8a!K31 -> 2 | H8: =IRC8a!L31 -> 1 | I8: =IRC8a!M31 -> 1 | J8: =AVERAGE(G8:I8) -> 1.3333333 | K8: =J8*0.1 -> 0.13333333
C9: C. Assessed, monitored and evaluated health status of 60%-79% (150-199) teaching and non-teaching personnel until first week of December of the current year. (10%) | D9: year round | F9: Secured approval for schedule of assessment and monitoring of individual health status. | G9: =IRC8a!K36 -> 2 | H9: =IRC8a!L36 -> 1 | I9: =IRC8a!M36 -> 1 | J9: =AVERAGE(G9:I9) -> 1.3333333 | K9: =J9*0.1 -> 0.13333333
C10: D. Provided nursing services to 8 activities/ programs/ trainings/ workshops/ seminars of the division, region or national with documentation until the first week of December of the current year. (20%) | D10: year round | F10: Communicated the schedule of provision of TA with SHN section. | G10: =IRC8a!K41 -> 2 | H10: =IRC8a!L41 -> 1 | I10: =IRC8a!M41 -> 1 | J10: =AVERAGE(G10:I10) -> 1.3333333 | K10: =J10*0.2 -> 0.26666667
B11: TECHNICAL ASSISTANCE | C11: A. Monitored the implementation of various health and nutrition programs to 5-6 assigned schools until the first week of December of the current year. (9%) | D11: year round | E11: 0.2 | F11: Communicated the schedule of monitoring with SHN section | G11: =IRC8a!K46 -> 2 | H11: =IRC8a!L46 -> 1 | I11: =IRC8a!M51 -> 1 | J11: =AVERAGE(G11:I11) -> 1.3333333 | K11: =J11*0.09 -> 0.12
C12: B. Provided technical assistance for various health and nutrition programs to 5-6 assigned schools until the first week of December of the current year. (9%) | D12: year round | F12: Provided technical assistance to various health and nutrition programs to schools with a Satisfactory Technical Assistance Feefback Rating. | G12: =IRC8a!K51 -> 2 | H12: =IRC8a!L51 -> 1 | I12: =IRC8a!M51 -> 1 | J12: =AVERAGE(G12:I12) -> 1.3333333 | K12: =J12*0.09 -> 0.12
C13: C. Monitored and provided Technical Assistance to the implementation of School Mental Health Program of at least 86-90% schools until the first week of December. (2%) | D13: year round | F13: Communicated the schedule of provision of monitoring and TA with SHN section. | G13: =IRC8a!K56 -> 2 | H13: =IRC8a!L56 -> 1 | I13: =IRC8a!M56 -> 1 | J13: =AVERAGE(G13:I13) -> 1.3333333 | K13: =J13*0.02 -> 0.026666667
F14: OVERALL RATING FOR ACCOMPLISHMENTS | K14: =SUM(K4:K13) -> 1.35
F15: ADJECTIVAL RATING | K15: {=_xlfn.IFS(K14>4.5,"O",K14>=3.5,"VS",K14>=2.5,"S",K14>=1.5,"US",K14<=1.49,"P")} -> P
A16: Rater-Ratee Agreement
A17: The signatures below confirm that the employee and his/her superior have agreed on content of this appraisal form and the performance rating.
B19: Name of Employee: | F19: Name of Superior:
B20: ARIAN MARIE B. SORIANO | F20: DR. JONATHAN P. DOMINGO
B21: NURSE II | F21: SGOD CHIEF
B22: Signature: | F22: Signature:
B24: Date: | F24: Date:

Sheet IRC9
A1: 2026 SGOD PERFORMANCE MONITORING AND EVALUATION SYSTEM (SGOD PMES)
A2: Individual Report Card No. 9-Performance Monitoring & Coaching Form (PMCF)
A4: Name: Arian Marie B. Soriano
A5: Position: Nurse II-SHN
A7: DATE | B7: CRITICAL INCIDENCE DESCRIPTION | C7: OUTPUT | D7: IMPACT ON JOB/
B8: (Actual events and behaviors reinforcing and hindering performance which are observed) | D8: ACTION PLAN
A9: April 1, 2026 | B9: In March, she exhibited outstanding dedication and commitment in carrying out her responsibilities as a TA provider. She offered valuable and insightful recommendations that were well received by customers, responded to their inquiries with patience, and ensured their needs were addressed efficiently and promptly. As a result, her efforts were acknowledged, earning her a perfect feedback rating of 4.00, equivalent to “very satisfactory.” | C9: A Very Satisfactory TA feedback rating, timely resolution of customer concerns, and provision of actionable recommendations. | D9: Her performance significantly reinforced her role by improving the efficiency and credibility of TA services, fostering customer trust, and establishing a high standard for service delivery within her team.
A10: June 19, 2026 | B10: During the Performance Monitoring and Coaching Session, she was instructed to review the SGOD Data Management System to assess her readiness for the Mid-Year Performance Review cum Workshop and to ensure alignment with her performance targets. The Means of Verification (MOVs) under each Key Result Area (KRA) and Objective were likewise examined in the system. In addition, the Individual Report Card (IRC) was reviewed to assess the status of updates covering the past five months. However, it was noted that the folders for each KRA and Objective, along with the corresponding MOVs, have not yet been uploaded in the Data Management System. Furthermore, the IRC sheets still require updating, and the IRC file name has not yet been revised to reflect Q2. Overall, she is advised to allocate sufficient time to complete the remaining deliverables to ensure full readiness for the upcoming Mid-Year Performance Review cum Workshop in July and to demonstrate full compliance with the required performance targets and documentation requirements. She is also reminded to regularly update her IRC to effectively monitor her performance targets and ensure continuous readiness for evaluation. | C10: Fully updated SGOD Data Management System with uploaded MOV folders per KRA and Objective, updated IRC sheets with correct Q2 file name, and consistently updated IRC reflecting five months of performance and aligned deliverables for Mid-Year Performance Review cum Workshop presentation. | D10: Ensures compliance with performance management requirements, improves accuracy and completeness of records, and strengthens alignment with targets. It also enhances monitoring of performance progress, supports timely evaluation readiness, and promotes accountability and effective documentation practices.
A12: Prepared by:
A15: DR. JONATHAN P. DOMINGO | D15: ARIAN MARIE B. SORIANO
A16: SGOD Chief | D16: Nurse II
